Workbook
Name Print_Area: 'centre 9'!$A$1:$T$24
Name Print_Area: 'centre nat'!$A$1:$T$40
Name Print_Area: 'centre REG'!$A$1:$T$29
Name Print_Area: liate5!$A$1:$U$107
Name Print_Area: NAT!$A$1:$T$275
Name Print_Area: REG!$A$1:$T$302

Sheet REG
A1: Acteur Dépense | B1: Type Dépense | C1: Sous Type Dépense | D1: Loi Finance | E1: Objet Dépense | F1: Nom Signataire | G1: Prénom Signataire | H1: Date Signature | I1: (Montant)NET | J1: Mode Engagement | K1: Rubrique
A2: 0113 | B2: SALIND | C2: FRAIS_CORRECTION | D2: 2025 | E2: FRAIS DE CORRECTION EXAMEN REGIONAL 1 ER ANNEE BAC | F2: RACHID | G2: RIANE | H2: 24/06/2024 | I2: 290816 | J2: PED_GLOBAL | K2: 5212011001912015153
A6: Grade/Echelle | B6: Date début | C6: Date fin | D6: Nombre | E6: Taux | F6: Brut | G6: Retenues | H6: Montant net | I6: CIN | J6: Nom | K6: Prénom | L6: DDR | M6: Mode de paiement | N6: Type référence règlement | O6: Banque | P6: Ville | Q6: Numéoro compte Ribé | R6: Clé | S6: objet règlement | T6: Reference
A7: PROF. DE L'ENS. SECOND. QUALIFIE GR. PRINCIPAL | B7: 31/05/2025 | C7: 10/06/2025 | D7: 60 | E7: 8 | F7: 480 | G7: 0 | H7: 480 | I7: K 164175 | J7: EL MADANI | K7: BACHIR | L7: 743793 | M7: VIR | N7: RIB | O7: =IF(L7="","",VLOOKUP(L7,'RIB 1'!A1:F9976,3,0)) -> 230 | P7: =IF(L7="","",VLOOKUP(L7,'RIB 1'!A1:F9976,4,0)) -> 640 | Q7: =IF(L7="","",VLOOKUP(L7,'RIB 1'!A1:F9976,5,0)) -> 8576464211011800 | R7: =IF(L7="","",VLOOKUP(L7,'RIB 1'!A1:F9976,6,0)) -> 91 | S7: FRAIS_CORRECTION
A8: PROF. DE L'ENS. SECOND. QUALIFIE 2EME GR. | B8: 31/05/2026 | C8: 10/06/2026 | D8: 59 | E8: 8 | F8: 472 | G8: 0 | H8: 472 | I8: AB821929 | J8: BENSLIMANE | K8: HADJER | L8: 1757976 | M8: VIR | N8: RIB | O8: =IF(L8="","",VLOOKUP(L8,'RIB 1'!A2:F9977,3,0)) -> 350 | P8: =IF(L8="","",VLOOKUP(L8,'RIB 1'!A2:F9977,4,0)) -> 810 | Q8: =IF(L8="","",VLOOKUP(L8,'RIB 1'!A2:F9977,5,0)) -> 0000000006102343 | R8: =IF(L8="","",VLOOKUP(L8,'RIB 1'!A2:F9977,6,0)) -> 51 | S8: FRAIS_CORRECTION
A9: PROF. DE L'ENS. SECOND. QUALIFIE 1ER GR. | B9: 31/05/2027 | C9: 10/06/2027 | D9: 120 | E9: 8 | F9: 960 | G9: 0 | H9: 960 | I9: GM79646 | J9: ZEROUAL | K9: OUSSAMA | L9: 1544261 | M9: VIR | N9: RIB | O9: =IF(L9="","",VLOOKUP(L9,'RIB 1'!A3:F9978,3,0)) -> 164 | P9: =IF(L9="","",VLOOKUP(L9,'RIB 1'!A3:F9978,4,0)) -> 640 | Q9: =IF(L9="","",VLOOKUP(L9,'RIB 1'!A3:F9978,5,0)) -> 2111199628740005 | R9: =IF(L9="","",VLOOKUP(L9,'RIB 1'!A3:F9978,6,0)) -> 68 | S9: FRAIS_CORRECTION
A10: PROF. DE L'ENS. SECOND. QUALIFIE 1ER GR. | B10: 31/05/2028 | C10: 10/06/2028 | D10: 120 | E10: 8 | F10: 960 | G10: 0 | H10: 960 | I10: LB127135 | J10: HOUTTI | K10: MOHAMED | L10: 1693032 | M10: VIR | N10: RIB | O10: =IF(L10="","",VLOOKUP(L10,'RIB 1'!A4:F9979,3,0)) -> 164 | P10: =IF(L10="","",VLOOKUP(L10,'RIB 1'!A4:F9979,4,0)) -> 640 | Q10: =IF(L10="","",VLOOKUP(L10,'RIB 1'!A4:F9979,5,0)) -> 2111123269890002 | R10: =IF(L10="","",VLOOKUP(L10,'RIB 1'!A4:F9979,6,0)) -> 31 | S10: FRAIS_CORRECTION
A11: PROF. DE L'ENS. SECOND. QUALIFIE 1ER GR. | B11: 31/05/2029 | C11: 10/06/2029 | D11: 120 | E11: 8 | F11: 960 | G11: 0 | H11: 960 | I11: G 428043 | J11: ESSAFI | K11: HICHAM | L11: 1722634 | M11: VIR | N11: RIB | O11: =IF(L11="","",VLOOKUP(L11,'RIB 1'!A5:F9980,3,0)) -> 007 | P11: =IF(L11="","",VLOOKUP(L11,'RIB 1'!A5:F9980,4,0)) -> 640 | Q11: =IF(L11="","",VLOOKUP(L11,'RIB 1'!A5:F9980,5,0)) -> 0004437000304069 | R11: =IF(L11="","",VLOOKUP(L11,'RIB 1'!A5:F9980,6,0)) -> 19 | S11: FRAIS_CORRECTION
A12: PROF. DE L'ENS. SECOND. QUALIFIE 2EME GR. | B12: 31/05/2030 | C12: 10/06/2030 | D12: 119 | E12: 8 | F12: 952 | G12: 0 | H12: 952 | I12: KB51078 | J12: EL MAATI | K12: BOUCHTA | L12: 1546515 | M12: VIR | N12: RIB | O12: =IF(L12="","",VLOOKUP(L12,'RIB 1'!A6:F9981,3,0)) -> 360 | P12: =IF(L12="","",VLOOKUP(L12,'RIB 1'!A6:F9981,4,0)) -> 640 | Q12: =IF(L12="","",VLOOKUP(L12,'RIB 1'!A6:F9981,5,0)) -> 0000086216850027 | R12: =IF(L12="","",VLOOKUP(L12,'RIB 1'!A6:F9981,6,0)) -> 20 | S12: FRAIS_CORRECTION
A13: PROF. DE L'ENS. SECOND. QUALIFIE 2EME GR. | B13: 31/05/2031 | C13: 10/06/2031 | D13: 60 | E13: 8 | F13: 480 | G13: 0 | H13: 480 | I13: K 199690 | J13: TLIDI | K13: ABDELAZIZ | L13: 1689331 | M13: VIR | N13: RIB | O13: =IF(L13="","",VLOOKUP(L13,'RIB 1'!A7:F9982,3,0)) -> 230 | P13: =IF(L13="","",VLOOKUP(L13,'RIB 1'!A7:F9982,4,0)) -> 640 | Q13: =IF(L13="","",VLOOKUP(L13,'RIB 1'!A7:F9982,5,0)) -> 4647269211011800 | R13: =IF(L13="","",VLOOKUP(L13,'RIB 1'!A7:F9982,6,0)) -> 74 | S13: FRAIS_CORRECTION
A14: PROF. DE L'ENS. SECOND. QUALIFIE 2EME GR. | B14: 31/05/2032 | C14: 10/06/2032 | D14: 120 | E14: 8 | F14: 960 | G14: 0 | H14: 960 | I14: HH4429 | J14: ANTAR | K14: FATIMA-EZZAHRA | L14: 1905442 | M14: VIR | N14: RIB | O14: =IF(L14="","",VLOOKUP(L14,'RIB 1'!A8:F9983,3,0)) -> 360 | P14: =IF(L14="","",VLOOKUP(L14,'RIB 1'!A8:F9983,4,0)) -> 640 | Q14: =IF(L14="","",VLOOKUP(L14,'RIB 1'!A8:F9983,5,0)) -> 0000049065490012 | R14: =IF(L14="","",VLOOKUP(L14,'RIB 1'!A8:F9983,6,0)) -> 67 | S14: FRAIS_CORRECTION
A15: PROF. DE L'ENS. SECOND. QUALIFIE 1ER GR. | B15: 31/05/2033 | C15: 10/06/2033 | D15: 120 | E15: 8 | F15: 960 | G15: 0 | H15: 960 | I15: LA100494 | J15: KCHIKICH | K15: BOUCHRA | L15: 1693025 | M15: VIR | N15: RIB | O15: =IF(L15="","",VLOOKUP(L15,'RIB 1'!A9:F9984,3,0)) -> 011 | P15: =IF(L15="","",VLOOKUP(L15,'RIB 1'!A9:F9984,4,0)) -> 640 | Q15: =IF(L15="","",VLOOKUP(L15,'RIB 1'!A9:F9984,5,0)) -> 0000162000003795 | R15: =IF(L15="","",VLOOKUP(L15,'RIB 1'!A9:F9984,6,0)) -> 27 | S15: FRAIS_CORRECTION
A16: PROF. DE L'ENS. SECOND. QUALIFIE 2EME GR. | B16: 31/05/2034 | C16: 10/06/2034 | D16: 60 | E16: 8 | F16: 480 | G16: 0 | H16: 480 | I16: K 450414 | J16: CHOJAA | K16: MOHAMED LARBI | L16: 1722620 | M16: VIR | N16: RIB | O16: =IF(L16="","",VLOOKUP(L16,'RIB 1'!A10:F9985,3,0)) -> 021 | P16: =IF(L16="","",VLOOKUP(L16,'RIB 1'!A10:F9985,4,0)) -> 640 | Q16: =IF(L16="","",VLOOKUP(L16,'RIB 1'!A10:F9985,5,0)) -> 0000233001063597 | R16: =IF(L16="","",VLOOKUP(L16,'RIB 1'!A10:F9985,6,0)) -> 95 | S16: FRAIS_CORRECTION
A17: PROF. DE L'ENS. SECOND. QUALIFIE 2EME GR. | B17: 31/05/2035 | C17: 10/06/2035 | D17: 180 | E17: 8 | F17: 1440 | G17: 0 | H17: 1440 | I17: K 510659 | J17: BAKKALI | K17: GHAZOUANI MOHAMMED | L17: 1906047 | M17: VIR | N17: RIB | O17: =IF(L17="","",VLOOKUP(L17,'RIB 1'!A11:F9986,3,0)) -> 230 | P17: =IF(L17="","",VLOOKUP(L17,'RIB 1'!A11:F9986,4,0)) -> 640 | Q17: =IF(L17="","",VLOOKUP(L17,'RIB 1'!A11:F9986,5,0)) -> 7539114211006000 | R17: =IF(L17="","",VLOOKUP(L17,'RIB 1'!A11:F9986,6,0)) -> 94 | S17: FRAIS_CORRECTION
A18: PROF. DE L'ENS. SECOND. QUALIFIE 2EME GR. | B18: 31/05/2036 | C18: 10/06/2036 | D18: 120 | E18: 8 | F18: 960 | G18: 0 | H18: 960 | I18: L 534627 | J18: BOUABADI | K18: YOUSRA | L18: 1966971 | M18: VIR | N18: RIB | O18: =IF(L18="","",VLOOKUP(L18,'RIB 1'!A12:F9987,3,0)) -> 164 | P18: =IF(L18="","",VLOOKUP(L18,'RIB 1'!A12:F9987,4,0)) -> 720 | Q18: =IF(L18="","",VLOOKUP(L18,'RIB 1'!A12:F9987,5,0)) -> 2111119126020007 | R18: =IF(L18="","",VLOOKUP(L18,'RIB 1'!A12:F9987,6,0)) -> 58 | S18: FRAIS_CORRECTION
... A279: PROF. DE L'ENS. SECOND. QUALIFIE GR. PRINCIPAL | B279: 31/05/2297 | C279: 10/06/2297 | D279: 159 | E279: 8 | F279: 1272 | G279: 0 | H279: 1272 | I279: KB29236 | J279: HAMMOUDAN | K279: MOHAMED | L279: 1543742 | M279: VIR | N279: RIB | O279: =IF(L279="","",VLOOKUP(L279,'RIB 1'!A273:F10248,3,0)) -> 360 | P279: =IF(L279="","",VLOOKUP(L279,'RIB 1'!A273:F10248,4,0)) -> 640 | Q279: =IF(L279="","",VLOOKUP(L279,'RIB 1'!A273:F10248,5,0)) -> 0000088502000017 | R279: =IF(L279="","",VLOOKUP(L279,'RIB 1'!A273:F10248,6,0)) -> 24 | S279: FRAIS_CORRECTION
A280: PROF. DE L'ENS. SECOND. QUALIFIE GR. PRINCIPAL | B280: 31/05/2298 | C280: 10/06/2298 | D280: 296 | E280: 8 | F280: 2368 | G280: 0 | H280: 2368 | I280: L 201585 | J280: MOUISSI | K280: ABDELILAH | L280: 270757 | M280: VIR | N280: RIB | O280: =IF(L280="","",VLOOKUP(L280,'RIB 1'!A274:F10249,3,0)) -> 164 | P280: =IF(L280="","",VLOOKUP(L280,'RIB 1'!A274:F10249,4,0)) -> 731 | Q280: =IF(L280="","",VLOOKUP(L280,'RIB 1'!A274:F10249,5,0)) -> 2111118859590004 | R280: =IF(L280="","",VLOOKUP(L280,'RIB 1'!A274:F10249,6,0)) -> 67 | S280: FRAIS_CORRECTION
A281: PROF. DE L'ENS. SECOND. QUALIFIE 1ER GR. | B281: 31/05/2299 | C281: 10/06/2299 | D281: 216 | E281: 8 | F281: 1728 | G281: 0 | H281: 1728 | I281: GM136140 | J281: EL KHAMALI | K281: ACHRAF | L281: 1905312 | M281: VIR | N281: RIB | O281: =IF(L281="","",VLOOKUP(L281,'RIB 1'!A275:F10250,3,0)) -> 164 | P281: =IF(L281="","",VLOOKUP(L281,'RIB 1'!A275:F10250,4,0)) -> 640 | Q281: =IF(L281="","",VLOOKUP(L281,'RIB 1'!A275:F10250,5,0)) -> 2111126947790007 | R281: =IF(L281="","",VLOOKUP(L281,'RIB 1'!A275:F10250,6,0)) -> 61 | S281: FRAIS_CORRECTION
A282: PROF. DE L'ENS. SECOND. QUALIFIE 1ER GR. | B282: 31/05/2300 | C282: 10/06/2300 | D282: 200 | E282: 8 | F282: 1600 | G282: 0 | H282: 1600 | I282: GM136140 | J282: EL KHAMALI | K282: ACHRAF | L282: 1905312 | M282: VIR | N282: RIB | O282: =IF(L282="","",VLOOKUP(L282,'RIB 1'!A276:F10251,3,0)) -> 164 | P282: =IF(L282="","",VLOOKUP(L282,'RIB 1'!A276:F10251,4,0)) -> 640 | Q282: =IF(L282="","",VLOOKUP(L282,'RIB 1'!A276:F10251,5,0)) -> 2111126947790007 | R282: =IF(L282="","",VLOOKUP(L282,'RIB 1'!A276:F10251,6,0)) -> 61 | S282: FRAIS_CORRECTION
A283: PROF. DE L'ENS. SECOND. QUALIFIE GR. PRINCIPAL | B283: 31/05/2301 | C283: 10/06/2301 | D283: 204 | E283: 8 | F283: 1632 | G283: 0 | H283: 1632 | I283: K 269379 | J283: EL MOUTAOUAKIL | K283: RACHID | L283: 1116569 | M283: VIR | N283: RIB | O283: =IF(L283="","",VLOOKUP(L283,'RIB 1'!A277:F10252,3,0)) -> 164 | P283: =IF(L283="","",VLOOKUP(L283,'RIB 1'!A277:F10252,4,0)) -> 640 | Q283: =IF(L283="","",VLOOKUP(L283,'RIB 1'!A277:F10252,5,0)) -> 2111150578090008 | R283: =IF(L283="","",VLOOKUP(L283,'RIB 1'!A277:F10252,6,0)) -> 95 | S283: FRAIS_CORRECTION
A284: PROF. DE L'ENS. SECOND. QUALIFIE GR. PRINCIPAL | B284: 31/05/2302 | C284: 10/06/2302 | D284: 270 | E284: 8 | F284: 2160 | G284: 0 | H284: 2160 | I284: K 269379 | J284: EL MOUTAOUAKIL | K284: RACHID | L284: 1116569 | M284: VIR | N284: RIB | O284: =IF(L284="","",VLOOKUP(L284,'RIB 1'!A278:F10253,3,0)) -> 164 | P284: =IF(L284="","",VLOOKUP(L284,'RIB 1'!A278:F10253,4,0)) -> 640 | Q284: =IF(L284="","",VLOOKUP(L284,'RIB 1'!A278:F10253,5,0)) -> 2111150578090008 | R284: =IF(L284="","",VLOOKUP(L284,'RIB 1'!A278:F10253,6,0)) -> 95 | S284: FRAIS_CORRECTION
A285: PROF. DE L'ENS. SECOND. QUALIFIE 2EME GR. | B285: 31/05/2303 | C285: 10/06/2303 | D285: 59 | E285: 8 | F285: 472 | G285: 0 | H285: 472 | I285: ZT223099 | J285: BILAL | K285: HOSNI | L285: 2155786 | M285: VIR | N285: RIB | O285: =IF(L285="","",VLOOKUP(L285,'RIB 1'!A279:F10254,3,0)) -> 164 | P285: =IF(L285="","",VLOOKUP(L285,'RIB 1'!A279:F10254,4,0)) -> 640 | Q285: =IF(L285="","",VLOOKUP(L285,'RIB 1'!A279:F10254,5,0)) -> 2111121643800002 | R285: =IF(L285="","",VLOOKUP(L285,'RIB 1'!A279:F10254,6,0)) -> 60 | S285: FRAIS_CORRECTION
A286: PROF. DE L'ENS. SECOND. QUALIFIE 1ER GR. | B286: 31/05/2304 | C286: 10/06/2304 | D286: 238 | E286: 8 | F286: 1904 | G286: 0 | H286: 1904 | I286: L 413159 | J286: MAFTOUMI | K286: SOUMIA | L286: 1592161 | M286: VIR | N286: RIB | O286: =IF(L286="","",VLOOKUP(L286,'RIB 1'!A280:F10255,3,0)) -> 225 | P286: =IF(L286="","",VLOOKUP(L286,'RIB 1'!A280:F10255,4,0)) -> 610 | Q286: =IF(L286="","",VLOOKUP(L286,'RIB 1'!A280:F10255,5,0)) -> 0017300856010120 | R286: =IF(L286="","",VLOOKUP(L286,'RIB 1'!A280:F10255,6,0)) -> 45 | S286: FRAIS_CORRECTION
A287: PROF. DE L'ENS. SECOND. QUALIFIE 2EME GR. | B287: 31/05/2305 | C287: 10/06/2305 | D287: 120 | E287: 8 | F287: 960 | G287: 0 | H287: 960 | I287: K 524194 | J287: BOUHARRAT | K287: SOULAIMAN | L287: 2048676 | M287: VIR | N287: RIB | O287: =IF(L287="","",VLOOKUP(L287,'RIB 1'!A281:F10256,3,0)) -> 350 | P287: =IF(L287="","",VLOOKUP(L287,'RIB 1'!A281:F10256,4,0)) -> 810 | Q287: =IF(L287="","",VLOOKUP(L287,'RIB 1'!A281:F10256,5,0)) -> 0000000008548993 | R287: =IF(L287="","",VLOOKUP(L287,'RIB 1'!A281:F10256,6,0)) -> 91 | S287: FRAIS_CORRECTION
A288: PROF. DE L'ENS. SECOND. QUALIFIE GR. PRINCIPAL | B288: 31/05/2306 | C288: 10/06/2306 | D288: 270 | E288: 8 | F288: 2160 | G288: 0 | H288: 2160 | I288: K 199481 | J288: BEN HACHMI | K288: MOHAMED LARBI | L288: 739129 | M288: VIR | N288: RIB | O288: =IF(L288="","",VLOOKUP(L288,'RIB 1'!A282:F10257,3,0)) -> 350 | P288: =IF(L288="","",VLOOKUP(L288,'RIB 1'!A282:F10257,4,0)) -> 810 | Q288: =IF(L288="","",VLOOKUP(L288,'RIB 1'!A282:F10257,5,0)) -> 0000000000425313 | R288: =IF(L288="","",VLOOKUP(L288,'RIB 1'!A282:F10257,6,0)) -> 75 | S288: FRAIS_CORRECTION
A289: PROF. DE L'ENS. SECOND. QUALIFIE GR. PRINCIPAL | B289: 31/05/2307 | C289: 10/06/2307 | D289: 267 | E289: 8 | F289: 2136 | G289: 0 | H289: 2136 | I289: K 199481 | J289: BEN HACHMI | K289: MOHAMED LARBI | L289: 739129 | M289: VIR | N289: RIB | O289: =IF(L289="","",VLOOKUP(L289,'RIB 1'!A283:F10258,3,0)) -> 350 | P289: =IF(L289="","",VLOOKUP(L289,'RIB 1'!A283:F10258,4,0)) -> 810 | Q289: =IF(L289="","",VLOOKUP(L289,'RIB 1'!A283:F10258,5,0)) -> 0000000000425313 | R289: =IF(L289="","",VLOOKUP(L289,'RIB 1'!A283:F10258,6,0)) -> 75 | S289: FRAIS_CORRECTION
A290: PROF. DE L'ENS. SECOND. QUALIFIE GR. PRINCIPAL | B290: 31/05/2308 | C290: 10/06/2308 | D290: 120 | E290: 8 | F290: 960 | G290: 0 | H290: 960 | I290: LA16069 | J290: BOUSSOUF | K290: MOHAMED LARBI | L290: 55924 | M290: VIR | N290: RIB | O290: =IF(L290="","",VLOOKUP(L290,'RIB 1'!A284:F10259,3,0)) -> 164 | P290: =IF(L290="","",VLOOKUP(L290,'RIB 1'!A284:F10259,4,0)) -> 640 | Q290: =IF(L290="","",VLOOKUP(L290,'RIB 1'!A284:F10259,5,0)) -> 2111173152600000 | R290: =IF(L290="","",VLOOKUP(L290,'RIB 1'!A284:F10259,6,0)) -> 56 | S290: FRAIS_CORRECTION
A291: PROF. DE L'ENS. SECOND. QUALIFIE 1ER GR. | B291: 31/05/2309 | C291: 10/06/2309 | D291: 178 | E291: 8 | F291: 1424 | G291: 0 | H291: 1424 | I291: L 274756 | J291: KERKECH | K291: ABDEL-LAH | L291: 1691344 | M291: VIR | N291: RIB | O291: =IF(L291="","",VLOOKUP(L291,'RIB 1'!A285:F10260,3,0)) -> 164 | P291: =IF(L291="","",VLOOKUP(L291,'RIB 1'!A285:F10260,4,0)) -> 640 | Q291: =IF(L291="","",VLOOKUP(L291,'RIB 1'!A285:F10260,5,0)) -> 2111186831450001 | R291: =IF(L291="","",VLOOKUP(L291,'RIB 1'!A285:F10260,6,0)) -> 05 | S291: FRAIS_CORRECTION
A292: PROF. DE L'ENS. SECOND. QUALIFIE GR. PRINCIPAL | B292: 31/05/2310 | C292: 10/06/2310 | D292: 60 | E292: 8 | F292: 480 | G292: 0 | H292: 480 | I292: GN111061 | J292: EL MIKALI | K292: ABDELHALIM | L292: 1503892 | M292: VIR | N292: RIB | O292: =IF(L292="","",VLOOKUP(L292,'RIB 1'!A286:F10261,3,0)) -> 363 | P292: =IF(L292="","",VLOOKUP(L292,'RIB 1'!A286:F10261,4,0)) -> 780 | Q292: =IF(L292="","",VLOOKUP(L292,'RIB 1'!A286:F10261,5,0)) -> 0000010000009207 | R292: =IF(L292="","",VLOOKUP(L292,'RIB 1'!A286:F10261,6,0)) -> 20 | S292: FRAIS_CORRECTION
... A302: PROF. DE L'ENS. SECOND. QUALIFIE 2EME GR. | B302: 31/05/2320 | C302: 10/06/2320 | D302: 60 | E302: 8 | F302: 480 | G302: 0 | H302: 480 | I302: LA50255 | J302: EL YOUSOUFY | K302: EL AYACHY | L302: 1599455 | M302: VIR | N302: RIB | O302: =IF(L302="","",VLOOKUP(L302,'RIB 1'!A296:F10271,3,0)) -> 164 | P302: =IF(L302="","",VLOOKUP(L302,'RIB 1'!A296:F10271,4,0)) -> 727 | Q302: =IF(L302="","",VLOOKUP(L302,'RIB 1'!A296:F10271,5,0)) -> 2111126408860000 | R302: =IF(L302="","",VLOOKUP(L302,'RIB 1'!A296:F10271,6,0)) -> 16 | S302: FRAIS_CORRECTION

Sheet centre nat
A1: Acteur Dépense | B1: Type Dépense | C1: Sous Type Dépense | D1: Loi Finance | E1: Objet Dépense | F1: Nom Signataire | G1: Prénom Signataire | H1: Date Signature | I1: (Montant)NET | J1: Mode Engagement | K1: Rubrique
A2: 0113 | B2: SALIND | D2: 2025 | E2: INDEMNITES POUR L'ORGANISATION DES EXAMENS ET CONCOURS 2 EME ANNEE BAC | F2: RACHID | G2: RIANE | H2: 27/06/2025 | I2: =SUM(H7:H40) -> 262800 | J2: PED_GLOBAL | K2: 5212011001912015153
A6: Grade/Echelle | B6: Date début | C6: Date fin | D6: Nombre | E6: Taux | F6: Brut | G6: Retenues | H6: Montant net | I6: CIN | J6: Nom | K6: Prénom | L6: DDR | M6: Mode de paiement | N6: Type référence règlement | O6: Banque | P6: Ville | Q6: Numéoro compte Ribé | R6: Clé | S6: objet règlement | T6: Reference
A7: PROF. DE L'ENS. SECOND. QUALIFIE GR. PRINCIPAL | B7: 28/05/2025 | C7: 27/06/2025 | D7: 30 | E7: 300 | F7: 9000 | G7: 0 | H7: 9000 | I7: FC18719 | J7: ABDOUS | K7: HABIBA | L7: 1276705 | M7: VIR | N7: RIB | O7: =IF(L7="","",VLOOKUP(L7,'RIB 1'!A1:F9976,3,0)) -> 164 | P7: =IF(L7="","",VLOOKUP(L7,'RIB 1'!A1:F9976,4,0)) -> 640 | Q7: =IF(L7="","",VLOOKUP(L7,'RIB 1'!A1:F9976,5,0)) -> 2111134184050002 | R7: =IF(L7="","",VLOOKUP(L7,'RIB 1'!A1:F9976,6,0)) -> 11 | S7: FRAIS_CORRECTION
A8: SPECIALISTE PEDAGOGIQUE DE 2EME GR. | B8: 28/05/2025 | C8: 27/06/2025 | D8: 30 | E8: 300 | F8: 9000 | G8: 0 | H8: 9000 | I8: LA76577 | J8: JBILOU | K8: SAMIR | L8: 1680403 | M8: VIR | N8: RIB | O8: =IF(L8="","",VLOOKUP(L8,'RIB 1'!A2:F9977,3,0)) -> 007 | P8: =IF(L8="","",VLOOKUP(L8,'RIB 1'!A2:F9977,4,0)) -> 640 | Q8: =IF(L8="","",VLOOKUP(L8,'RIB 1'!A2:F9977,5,0)) -> 0004422000304570 | R8: =IF(L8="","",VLOOKUP(L8,'RIB 1'!A2:F9977,6,0)) -> 46 | S8: FRAIS_CORRECTION
A9: PROF. DE L'ENS. PRIMAIRE 1ER GR. | B9: 28/05/2025 | C9: 27/06/2025 | D9: 30 | E9: 300 | F9: 9000 | G9: 0 | H9: 9000 | I9: K 250280 | J9: EL FARGANI | K9: MOHAMED | L9: 1116474 | M9: VIR | N9: RIB | O9: =IF(L9="","",VLOOKUP(L9,'RIB 1'!A3:F9978,3,0)) -> 011 | P9: =IF(L9="","",VLOOKUP(L9,'RIB 1'!A3:F9978,4,0)) -> 640 | Q9: =IF(L9="","",VLOOKUP(L9,'RIB 1'!A3:F9978,5,0)) -> 0000072000006717 | R9: =IF(L9="","",VLOOKUP(L9,'RIB 1'!A3:F9978,6,0)) -> 53 | S9: FRAIS_CORRECTION
A10: SPECIALISTE D'ECONOM. ET D'ADMIN. DE 1ER GR. | B10: 28/05/2025 | C10: 27/06/2025 | D10: 30 | E10: 300 | F10: 9000 | G10: 0 | H10: 9000 | I10: K 259084 | J10: ABJAYOU | K10: MOHAMMED | L10: 1116506 | M10: VIR | N10: RIB | O10: =IF(L10="","",VLOOKUP(L10,'RIB 1'!A4:F9979,3,0)) -> 164 | P10: =IF(L10="","",VLOOKUP(L10,'RIB 1'!A4:F9979,4,0)) -> 640 | Q10: =IF(L10="","",VLOOKUP(L10,'RIB 1'!A4:F9979,5,0)) -> 2111155612930002 | R10: =IF(L10="","",VLOOKUP(L10,'RIB 1'!A4:F9979,6,0)) -> 13 | S10: FRAIS_CORRECTION
A11: SPECIALISTE D'ECONOM. ET D'ADMIN. DE 1ER GR. | B11: 28/05/2025 | C11: 27/06/2025 | D11: 30 | E11: 300 | F11: 9000 | G11: 0 | H11: 9000 | I11: K 209741 | J11: SBAYJI | K11: MOHAMMED SAID | L11: 57611 | M11: VIR | N11: RIB | O11: =IF(L11="","",VLOOKUP(L11,'RIB 1'!A5:F9980,3,0)) -> 164 | P11: =IF(L11="","",VLOOKUP(L11,'RIB 1'!A5:F9980,4,0)) -> 640 | Q11: =IF(L11="","",VLOOKUP(L11,'RIB 1'!A5:F9980,5,0)) -> 2111153307550003 | R11: =IF(L11="","",VLOOKUP(L11,'RIB 1'!A5:F9980,6,0)) -> 46 | S11: FRAIS_CORRECTION
A12: CONSEILLERS EN PLANIFICATION DE L'EDUCATION 1ER GRADE | B12: 28/05/2025 | C12: 27/06/2025 | D12: 24 | E12: 300 | F12: 7200 | G12: 0 | H12: 7200 | I12: AB51048 | J12: FAOUZI | K12: MAROUANE | L12: 1598468 | M12: VIR | N12: RIB | O12: =IF(L12="","",VLOOKUP(L12,'RIB 1'!A6:F9981,3,0)) -> 225 | P12: =IF(L12="","",VLOOKUP(L12,'RIB 1'!A6:F9981,4,0)) -> 150 | Q12: =IF(L12="","",VLOOKUP(L12,'RIB 1'!A6:F9981,5,0)) -> 0349059386010126 | R12: =IF(L12="","",VLOOKUP(L12,'RIB 1'!A6:F9981,6,0)) -> 81 | S12: FRAIS_CORRECTION
A13: SPECIALISTE D'ECONOM. ET D'ADMIN. DE 1ER GR. | B13: 28/05/2025 | C13: 27/06/2025 | D13: 30 | E13: 300 | F13: 9000 | G13: 0 | H13: 9000 | I13: K 239856 | J13: CHARAB | K13: BADREDDINE | L13: 55990 | M13: VIR | N13: RIB | O13: =IF(L13="","",VLOOKUP(L13,'RIB 1'!A7:F9982,3,0)) -> 164 | P13: =IF(L13="","",VLOOKUP(L13,'RIB 1'!A7:F9982,4,0)) -> 640 | Q13: =IF(L13="","",VLOOKUP(L13,'RIB 1'!A7:F9982,5,0)) -> 2111133277330008 | R13: =IF(L13="","",VLOOKUP(L13,'RIB 1'!A7:F9982,6,0)) -> 51 | S13: FRAIS_CORRECTION
A14: ADJOINT PEDAGOGIQUE DE 4EME GRADE | B14: 28/05/2025 | C14: 27/06/2025 | D14: 30 | E14: 300 | F14: 9000 | G14: 0 | H14: 9000 | I14: K 230978 | J14: CHEOUATI | K14: AHMED | L14: 1403729 | M14: VIR | N14: RIB | O14: =IF(L14="","",VLOOKUP(L14,'RIB 1'!A8:F9983,3,0)) -> 164 | P14: =IF(L14="","",VLOOKUP(L14,'RIB 1'!A8:F9983,4,0)) -> 640 | Q14: =IF(L14="","",VLOOKUP(L14,'RIB 1'!A8:F9983,5,0)) -> 2111133319680014 | R14: =IF(L14="","",VLOOKUP(L14,'RIB 1'!A8:F9983,6,0)) -> 51 | S14: FRAIS_CORRECTION
A15: ADJOINT PEDAGOGIQUE DE 5EME GRADE | B15: 28/05/2025 | C15: 27/06/2025 | D15: 30 | E15: 300 | F15: 9000 | G15: 0 | H15: 9000 | I15: K 149401 | J15: MAIMOUNI | K15: MOHAMMED | L15: 1310759 | M15: VIR | N15: RIB | O15: =IF(L15="","",VLOOKUP(L15,'RIB 1'!A9:F9984,3,0)) -> 164 | P15: =IF(L15="","",VLOOKUP(L15,'RIB 1'!A9:F9984,4,0)) -> 640 | Q15: =IF(L15="","",VLOOKUP(L15,'RIB 1'!A9:F9984,5,0)) -> 2111178014970004 | R15: =IF(L15="","",VLOOKUP(L15,'RIB 1'!A9:F9984,6,0)) -> 13 | S15: FRAIS_CORRECTION
A16: ADJOINT PEDAGOGIQUE DE 4EME GRADE | B16: 28/05/2025 | C16: 27/06/2025 | D16: 30 | E16: 300 | F16: 9000 | G16: 0 | H16: 9000 | I16: K 251744 | J16: BELHADRI | K16: MAROUANE | L16: 1398949 | M16: VIR | N16: RIB | O16: =IF(L16="","",VLOOKUP(L16,'RIB 1'!A10:F9985,3,0)) -> 230 | P16: =IF(L16="","",VLOOKUP(L16,'RIB 1'!A10:F9985,4,0)) -> 640 | Q16: =IF(L16="","",VLOOKUP(L16,'RIB 1'!A10:F9985,5,0)) -> 5589759211011800 | R16: =IF(L16="","",VLOOKUP(L16,'RIB 1'!A10:F9985,6,0)) -> 78 | S16: FRAIS_CORRECTION
A17: ADJOINT PEDAGOGIQUE DE 4EME GRADE | B17: 28/05/2025 | C17: 27/06/2025 | D17: 30 | E17: 300 | F17: 9000 | G17: 0 | H17: 9000 | I17: K 176035 | J17: AOUDAIR | K17: MOHAMED | L17: 1310711 | M17: VIR | N17: RIB | O17: =IF(L17="","",VLOOKUP(L17,'RIB 1'!A11:F9986,3,0)) -> 164 | P17: =IF(L17="","",VLOOKUP(L17,'RIB 1'!A11:F9986,4,0)) -> 640 | Q17: =IF(L17="","",VLOOKUP(L17,'RIB 1'!A11:F9986,5,0)) -> 2111133175420000 | R17: =IF(L17="","",VLOOKUP(L17,'RIB 1'!A11:F9986,6,0)) -> 43 | S17: FRAIS_CORRECTION
A18: ADJOINT PEDAGOGIQUE DE 4EME GRADE | B18: 28/05/2025 | C18: 27/06/2025 | D18: 14 | E18: 300 | F18: 4200 | G18: 0 | H18: 4200 | I18: K 252545 | J18: EL HAOUAT | K18: ES SAID | L18: 1441504 | M18: VIR | N18: RIB | O18: =IF(L18="","",VLOOKUP(L18,'RIB 1'!A12:F9987,3,0)) -> 011 | P18: =IF(L18="","",VLOOKUP(L18,'RIB 1'!A12:F9987,4,0)) -> 640 | Q18: =IF(L18="","",VLOOKUP(L18,'RIB 1'!A12:F9987,5,0)) -> 0000212000006039 | R18: =IF(L18="","",VLOOKUP(L18,'RIB 1'!A12:F9987,6,0)) -> 29 | S18: FRAIS_CORRECTION
... A34: ADMINISTRATEUR DE L’EDUCA. NAT. DE GR. PRINCIPAL | B34: 28/05/2025 | C34: 27/06/2025 | D34: 22 | E34: 300 | F34: 6600 | G34: 0 | H34: 6600 | I34: R 210776 | J34: AKRI | K34: MARZOUK | L34: 1234235 | M34: VIR | N34: RIB | O34: =IF(L34="","",VLOOKUP(L34,'RIB 1'!A28:F10003,3,0)) -> 164 | P34: =IF(L34="","",VLOOKUP(L34,'RIB 1'!A28:F10003,4,0)) -> 640 | Q34: =IF(L34="","",VLOOKUP(L34,'RIB 1'!A28:F10003,5,0)) -> 2111172219930004 | R34: =IF(L34="","",VLOOKUP(L34,'RIB 1'!A28:F10003,6,0)) -> 36 | S34: FRAIS_CORRECTION
A35: PROF. DE L'ENS. SECOND. COLLEGIAL 1ER GR. | B35: 28/05/2025 | C35: 27/06/2025 | D35: 30 | E35: 300 | F35: 9000 | G35: 0 | H35: 9000 | I35: K 214828 | J35: ROUDANI | K35: ABDELAZIZ | L35: 1045515 | M35: VIR | N35: RIB | O35: 362 | P35: 640 | Q35: 0011112000806128 | R35: 85 | S35: FRAIS_CORRECTION
A36: ADMINISTRATEUR DE 2ER GRADE | B36: 28/05/2025 | C36: 27/06/2025 | D36: 10 | E36: 300 | F36: 3000 | G36: 0 | H36: 3000 | I36: UC109984 | J36: OULKHANG | K36: ISMAIL | L36: 1401819 | M36: VIR | N36: RIB | O36: =IF(L36="","",VLOOKUP(L36,'RIB 1'!A30:F10005,3,0)) -> 164 | P36: =IF(L36="","",VLOOKUP(L36,'RIB 1'!A30:F10005,4,0)) -> 640 | Q36: =IF(L36="","",VLOOKUP(L36,'RIB 1'!A30:F10005,5,0)) -> 2111175844190001 | R36: =IF(L36="","",VLOOKUP(L36,'RIB 1'!A30:F10005,6,0)) -> 97 | S36: FRAIS_CORRECTION
A37: INGENIEUR EN CHEF 1er GRADE | B37: 28/05/2025 | C37: 27/06/2025 | D37: 10 | E37: 300 | F37: 3000 | G37: 0 | H37: 3000 | I37: K 178247 | J37: SABIR | K37: AZIZ | L37: 845722 | M37: VIR | N37: RIB | O37: =IF(L37="","",VLOOKUP(L37,'RIB 1'!A31:F10006,3,0)) -> 164 | P37: =IF(L37="","",VLOOKUP(L37,'RIB 1'!A31:F10006,4,0)) -> 640 | Q37: =IF(L37="","",VLOOKUP(L37,'RIB 1'!A31:F10006,5,0)) -> 2111172219930004 | R37: =IF(L37="","",VLOOKUP(L37,'RIB 1'!A31:F10006,6,0)) -> 36 | S37: FRAIS_CORRECTION
A38: ADJOINT PEDAGOGIQUE DE 4EME GRADE | B38: 28/05/2025 | C38: 27/06/2025 | D38: 30 | E38: 300 | F38: 9000 | G38: 0 | H38: 9000 | I38: K 160477 | J38: MAIMOUNI | K38: MALIKA | L38: 1441505 | M38: VIR | N38: RIB | O38: =IF(L38="","",VLOOKUP(L38,'RIB 1'!A32:F10007,3,0)) -> 007 | P38: =IF(L38="","",VLOOKUP(L38,'RIB 1'!A32:F10007,4,0)) -> 640 | Q38: =IF(L38="","",VLOOKUP(L38,'RIB 1'!A32:F10007,5,0)) -> 0002448000306754 | R38: =IF(L38="","",VLOOKUP(L38,'RIB 1'!A32:F10007,6,0)) -> 66 | S38: FRAIS_CORRECTION
A39: PROF. DE L'ENS. SECOND. COLLEGIAL 2EME GR. | B39: 28/05/2025 | C39: 27/06/2025 | D39: 14 | E39: 300 | F39: 4200 | G39: 0 | H39: 4200 | I39: FB78767 | J39: EL BAGHDADI | K39: ABDALLAH | L39: 1686731 | M39: VIR | N39: RIB | O39: 164 | P39: 640 | Q39: 2111140873040006 | R39: 59 | S39: FRAIS_CORRECTION
A40: SPECIALISTE PEDAGOGIQUE DE 1ER GR. | B40: 28/05/2025 | C40: 27/06/2025 | D40: 14 | E40: 300 | F40: 4200 | G40: 0 | H40: 4200 | I40: LB90118 | J40: EL OUAZZANI | K40: MUSTAPHA | L40: 1680535 | M40: VIR | N40: RIB | O40: =IF(L40="","",VLOOKUP(L40,'RIB 1'!A34:F10009,3,0)) -> 225 | P40: =IF(L40="","",VLOOKUP(L40,'RIB 1'!A34:F10009,4,0)) -> 780 | Q40: =IF(L40="","",VLOOKUP(L40,'RIB 1'!A34:F10009,5,0)) -> 0652000476010116 | R40: =IF(L40="","",VLOOKUP(L40,'RIB 1'!A34:F10009,6,0)) -> 42 | S40: FRAIS_CORRECTION

Sheet centre REG
A1: Acteur Dépense | B1: Type Dépense | C1: Sous Type Dépense | D1: Loi Finance | E1: Objet Dépense | F1: Nom Signataire | G1: Prénom Signataire | H1: Date Signature | I1: (Montant)NET | J1: Mode Engagement | K1: Rubrique
A2: 0113 | B2: SALIND | D2: 2025 | E2: INDEMNITES POUR L'ORGANISATION DES EXAMENS ET CONCOURS 2 EME ANNEE BAC | F2: RACHID | G2: RIANE | H2: 27/06/2025 | I2: =SUM(H7:H29) -> 40200 | J2: PED_GLOBAL | K2: 5212011001912015153
A6: Grade/Echelle | B6: Date début | C6: Date fin | D6: Nombre | E6: Taux | F6: Brut | G6: Retenues | H6: Montant net | I6: CIN | J6: Nom | K6: Prénom | L6: DDR | M6: Mode de paiement | N6: Type référence règlement | O6: Banque | P6: Ville | Q6: Numéoro compte Ribé | R6: Clé | S6: objet règlement | T6: Reference
A7: PROF. DE L'ENS. SECOND. QUALIFIE GR. PRINCIPAL | B7: 28/05/2025 | C7: 27/06/2025 | D7: 6 | E7: 300 | F7: 1800 | G7: 0 | H7: 1800 | I7: FC18719 | J7: ABDOUS | K7: HABIBA | L7: 1276705 | M7: VIR | N7: RIB | O7: =IF(L7="","",VLOOKUP(L7,'RIB 1'!A1:F9976,3,0)) -> 164 | P7: =IF(L7="","",VLOOKUP(L7,'RIB 1'!A1:F9976,4,0)) -> 640 | Q7: =IF(L7="","",VLOOKUP(L7,'RIB 1'!A1:F9976,5,0)) -> 2111134184050002 | R7: =IF(L7="","",VLOOKUP(L7,'RIB 1'!A1:F9976,6,0)) -> 11 | S7: FRAIS_CORRECTION
A8: SPECIALISTE PEDAGOGIQUE DE 2EME GR. | B8: 28/05/2025 | C8: 27/06/2025 | D8: 6 | E8: 300 | F8: 1800 | G8: 0 | H8: 1800 | I8: LA76577 | J8: JBILOU | K8: SAMIR | L8: 1680403 | M8: VIR | N8: RIB | O8: =IF(L8="","",VLOOKUP(L8,'RIB 1'!A2:F9977,3,0)) -> 007 | P8: =IF(L8="","",VLOOKUP(L8,'RIB 1'!A2:F9977,4,0)) -> 640 | Q8: =IF(L8="","",VLOOKUP(L8,'RIB 1'!A2:F9977,5,0)) -> 0004422000304570 | R8: =IF(L8="","",VLOOKUP(L8,'RIB 1'!A2:F9977,6,0)) -> 46 | S8: FRAIS_CORRECTION
A9: PROF. DE L'ENS. PRIMAIRE 1ER GR. | B9: 28/05/2025 | C9: 27/06/2025 | D9: 6 | E9: 300 | F9: 1800 | G9: 0 | H9: 1800 | I9: K 250280 | J9: EL FARGANI | K9: MOHAMED | L9: 1116474 | M9: VIR | N9: RIB | O9: =IF(L9="","",VLOOKUP(L9,'RIB 1'!A3:F9978,3,0)) -> 011 | P9: =IF(L9="","",VLOOKUP(L9,'RIB 1'!A3:F9978,4,0)) -> 640 | Q9: =IF(L9="","",VLOOKUP(L9,'RIB 1'!A3:F9978,5,0)) -> 0000072000006717 | R9: =IF(L9="","",VLOOKUP(L9,'RIB 1'!A3:F9978,6,0)) -> 53 | S9: FRAIS_CORRECTION
A10: SPECIALISTE D'ECONOM. ET D'ADMIN. DE 1ER GR. | B10: 28/05/2025 | C10: 27/06/2025 | D10: 6 | E10: 300 | F10: 1800 | G10: 0 | H10: 1800 | I10: K 259084 | J10: ABJAYOU | K10: MOHAMMED | L10: 1116506 | M10: VIR | N10: RIB | O10: =IF(L10="","",VLOOKUP(L10,'RIB 1'!A4:F9979,3,0)) -> 164 | P10: =IF(L10="","",VLOOKUP(L10,'RIB 1'!A4:F9979,4,0)) -> 640 | Q10: =IF(L10="","",VLOOKUP(L10,'RIB 1'!A4:F9979,5,0)) -> 2111155612930002 | R10: =IF(L10="","",VLOOKUP(L10,'RIB 1'!A4:F9979,6,0)) -> 13 | S10: FRAIS_CORRECTION
A11: SPECIALISTE D'ECONOM. ET D'ADMIN. DE 1ER GR. | B11: 28/05/2025 | C11: 27/06/2025 | D11: 6 | E11: 300 | F11: 1800 | G11: 0 | H11: 1800 | I11: K 209741 | J11: SBAYJI | K11: MOHAMMED SAID | L11: 57611 | M11: VIR | N11: RIB | O11: =IF(L11="","",VLOOKUP(L11,'RIB 1'!A5:F9980,3,0)) -> 164 | P11: =IF(L11="","",VLOOKUP(L11,'RIB 1'!A5:F9980,4,0)) -> 640 | Q11: =IF(L11="","",VLOOKUP(L11,'RIB 1'!A5:F9980,5,0)) -> 2111153307550003 | R11: =IF(L11="","",VLOOKUP(L11,'RIB 1'!A5:F9980,6,0)) -> 46 | S11: FRAIS_CORRECTION
A12: SPECIALISTE D'ECONOM. ET D'ADMIN. DE 1ER GR. | B12: 28/05/2025 | C12: 27/06/2025 | D12: 6 | E12: 300 | F12: 1800 | G12: 0 | H12: 1800 | I12: K 239856 | J12: CHARAB | K12: BADREDDINE | L12: 55990 | M12: VIR | N12: RIB | O12: =IF(L12="","",VLOOKUP(L12,'RIB 1'!A6:F9981,3,0)) -> 164 | P12: =IF(L12="","",VLOOKUP(L12,'RIB 1'!A6:F9981,4,0)) -> 640 | Q12: =IF(L12="","",VLOOKUP(L12,'RIB 1'!A6:F9981,5,0)) -> 2111133277330008 | R12: =IF(L12="","",VLOOKUP(L12,'RIB 1'!A6:F9981,6,0)) -> 51 | S12: FRAIS_CORRECTION
A13: ADJOINT PEDAGOGIQUE DE 4EME GRADE | B13: 28/05/2025 | C13: 27/06/2025 | D13: 6 | E13: 300 | F13: 1800 | G13: 0 | H13: 1800 | I13: K 230978 | J13: CHEOUATI | K13: AHMED | L13: 1403729 | M13: VIR | N13: RIB | O13: =IF(L13="","",VLOOKUP(L13,'RIB 1'!A7:F9982,3,0)) -> 164 | P13: =IF(L13="","",VLOOKUP(L13,'RIB 1'!A7:F9982,4,0)) -> 640 | Q13: =IF(L13="","",VLOOKUP(L13,'RIB 1'!A7:F9982,5,0)) -> 2111133319680014 | R13: =IF(L13="","",VLOOKUP(L13,'RIB 1'!A7:F9982,6,0)) -> 51 | S13: FRAIS_CORRECTION
A14: ADJOINT PEDAGOGIQUE DE 5EME GRADE | B14: 28/05/2025 | C14: 27/06/2025 | D14: 6 | E14: 300 | F14: 1800 | G14: 0 | H14: 1800 | I14: K 149401 | J14: MAIMOUNI | K14: MOHAMMED | L14: 1310759 | M14: VIR | N14: RIB | O14: =IF(L14="","",VLOOKUP(L14,'RIB 1'!A8:F9983,3,0)) -> 164 | P14: =IF(L14="","",VLOOKUP(L14,'RIB 1'!A8:F9983,4,0)) -> 640 | Q14: =IF(L14="","",VLOOKUP(L14,'RIB 1'!A8:F9983,5,0)) -> 2111178014970004 | R14: =IF(L14="","",VLOOKUP(L14,'RIB 1'!A8:F9983,6,0)) -> 13 | S14: FRAIS_CORRECTION
A15: ADJOINT PEDAGOGIQUE DE 4EME GRADE | B15: 28/05/2025 | C15: 27/06/2025 | D15: 6 | E15: 300 | F15: 1800 | G15: 0 | H15: 1800 | I15: K 251744 | J15: BELHADRI | K15: MAROUANE | L15: 1398949 | M15: VIR | N15: RIB | O15: =IF(L15="","",VLOOKUP(L15,'RIB 1'!A9:F9984,3,0)) -> 230 | P15: =IF(L15="","",VLOOKUP(L15,'RIB 1'!A9:F9984,4,0)) -> 640 | Q15: =IF(L15="","",VLOOKUP(L15,'RIB 1'!A9:F9984,5,0)) -> 5589759211011800 | R15: =IF(L15="","",VLOOKUP(L15,'RIB 1'!A9:F9984,6,0)) -> 78 | S15: FRAIS_CORRECTION
A16: ADJOINT PEDAGOGIQUE DE 4EME GRADE | B16: 28/05/2025 | C16: 27/06/2025 | D16: 6 | E16: 300 | F16: 1800 | G16: 0 | H16: 1800 | I16: K 176035 | J16: AOUDAIR | K16: MOHAMED | L16: 1310711 | M16: VIR | N16: RIB | O16: =IF(L16="","",VLOOKUP(L16,'RIB 1'!A10:F9985,3,0)) -> 164 | P16: =IF(L16="","",VLOOKUP(L16,'RIB 1'!A10:F9985,4,0)) -> 640 | Q16: =IF(L16="","",VLOOKUP(L16,'RIB 1'!A10:F9985,5,0)) -> 2111133175420000 | R16: =IF(L16="","",VLOOKUP(L16,'RIB 1'!A10:F9985,6,0)) -> 43 | S16: FRAIS_CORRECTION
A17: PROF. DE L'ENS. SECOND. COLLEGIAL 1ER GR. | B17: 28/05/2025 | C17: 27/06/2025 | D17: 4 | E17: 300 | F17: 1200 | G17: 0 | H17: 1200 | I17: UB74512 | J17: MIDOUL | K17: KARIM | L17: 1755082 | M17: VIR | N17: RIB | O17: =IF(L17="","",VLOOKUP(L17,'RIB 1'!A11:F9986,3,0)) -> 164 | P17: =IF(L17="","",VLOOKUP(L17,'RIB 1'!A11:F9986,4,0)) -> 640 | Q17: =IF(L17="","",VLOOKUP(L17,'RIB 1'!A11:F9986,5,0)) -> 2111100196790000 | R17: =IF(L17="","",VLOOKUP(L17,'RIB 1'!A11:F9986,6,0)) -> 30 | S17: FRAIS_CORRECTION
A18: PROF. DE L'ENS. SECOND. COLLEGIAL 2EME GR. | B18: 28/05/2025 | C18: 27/06/2025 | D18: 4 | E18: 300 | F18: 1200 | G18: 0 | H18: 1200 | I18: R 289153 | J18: BALAH | K18: MOHAMED | L18: 1686652 | M18: VIR | N18: RIB | O18: =IF(L18="","",VLOOKUP(L18,'RIB 1'!A12:F9987,3,0)) -> 164 | P18: =IF(L18="","",VLOOKUP(L18,'RIB 1'!A12:F9987,4,0)) -> 640 | Q18: =IF(L18="","",VLOOKUP(L18,'RIB 1'!A12:F9987,5,0)) -> 2111140850920006 | R18: =IF(L18="","",VLOOKUP(L18,'RIB 1'!A12:F9987,6,0)) -> 31 | S18: FRAIS_CORRECTION
... A26: PROF. DE L'ENS. SECOND. COLLEGIAL 1ER GR. | B26: 28/05/2025 | C26: 27/06/2025 | D26: 6 | E26: 300 | F26: 1800 | G26: 0 | H26: 1800 | I26: C 625277 | J26: MAMAD | K26: BRAHIM | L26: 57348 | M26: VIR | N26: RIB | O26: =IF(L26="","",VLOOKUP(L26,'RIB 1'!A20:F9995,3,0)) -> 164 | P26: =IF(L26="","",VLOOKUP(L26,'RIB 1'!A20:F9995,4,0)) -> 640 | Q26: =IF(L26="","",VLOOKUP(L26,'RIB 1'!A20:F9995,5,0)) -> 2111139303560005 | R26: =IF(L26="","",VLOOKUP(L26,'RIB 1'!A20:F9995,6,0)) -> 19 | S26: FRAIS_CORRECTION
A27: PROF. DE L'ENS. SECOND. COLLEGIAL 1ER GR. | B27: 28/05/2025 | C27: 27/06/2025 | D27: 6 | E27: 300 | F27: 1800 | G27: 0 | H27: 1800 | I27: K 214828 | J27: ROUDANI | K27: ABDELAZIZ | L27: 1045515 | M27: VIR | N27: RIB | O27: 362 | P27: 640 | Q27: 0011112000806128 | R27: 85 | S27: FRAIS_CORRECTION
A28: PROF. DE L'ENS. SECOND. QUALIFIE GR. PRINCIPAL | B28: 28/05/2025 | C28: 27/06/2025 | D28: 6 | E28: 300 | F28: 1800 | G28: 0 | H28: 1800 | I28: GB2274 | J28: EL MESBAHI | K28: ABDELMAJID | L28: 776186 | M28: VIR | N28: RIB | O28: =IF(L28="","",VLOOKUP(L28,'RIB 1'!A22:F9997,3,0)) -> 011 | P28: =IF(L28="","",VLOOKUP(L28,'RIB 1'!A22:F9997,4,0)) -> 640 | Q28: =IF(L28="","",VLOOKUP(L28,'RIB 1'!A22:F9997,5,0)) -> 0000082000001559 | R28: =IF(L28="","",VLOOKUP(L28,'RIB 1'!A22:F9997,6,0)) -> 54 | S28: FRAIS_CORRECTION
A29: ADJOINT PEDAGOGIQUE DE 4EME GRADE | B29: 28/05/2025 | C29: 27/06/2025 | D29: 6 | E29: 300 | F29: 1800 | G29: 0 | H29: 1800 | I29: K 160477 | J29: MAIMOUNI | K29: MALIKA | L29: 1441505 | M29: VIR | N29: RIB | O29: =IF(L29="","",VLOOKUP(L29,'RIB 1'!A23:F9998,3,0)) -> 007 | P29: =IF(L29="","",VLOOKUP(L29,'RIB 1'!A23:F9998,4,0)) -> 640 | Q29: =IF(L29="","",VLOOKUP(L29,'RIB 1'!A23:F9998,5,0)) -> 0002448000306754 | R29: =IF(L29="","",VLOOKUP(L29,'RIB 1'!A23:F9998,6,0)) -> 66 | S29: FRAIS_CORRECTION

Sheet base
A1: PPR | B1: CIN | C1: NOML | D1: NOM_FR | E1: PRENOM_FR | F1: GRADE FR | G1: GRADE | H1: ECHELON | I1: INDICE | J1: TX IR
A2: 78535 | B2: CB28999 | C2: BOUCHRA NAIM | D2: NAIM | E2: BOUCHRA | F2: ADMINISTRATEUR DE 1ER GRADE | G2: 1 | H2: 1 | I2: 704 | J2: 0.34
A3: 730373 | B3: E 147469 | C3: FATIHA NHOU | D3: NHOU | E3: FATIHA | F3: REDACTEUR 1ER GRADE | G3: 1 | H3: 10 | I3: 639 | J3: 0.38
A4: 838519 | B4: BE96831 | C4: RABIA EDDAHABI | D4: EDDAHABI | E4: RABIA | F4: ADMINISTRATEUR DE 2ER GRADE | G4: 2 | H4: 10 | I4: 639 | J4: 0.34
A5: 838738 | B5: AB100528 | C5: KAMAL CHIBOUB | D5: CHIBOUB | E5: KAMAL | F5: ADMINISTRATEUR DE 1ER GRADE | G5: 1 | H5: 1 | I5: 704 | J5: 0.34
A6: 1048405 | B6: LB47808 | C6: TAHRIOUI RACHID | D6: TAHRIOUI | E6: RACHID | F6: PROF. DE L'ENS. SECOND. QUALIFIE GR. PRINCIPAL | G6: HE | H6: 4 | I6: 812 | J6: 0.38
A7: 1053154 | B7: LF3058 | C7: BENYAYA KHADIJA | D7: BEN YAYA | E7: KHADIJA | F7: PROF. DE L'ENS. SECOND. QUALIFIE GR. PRINCIPAL | G7: HE | H7: 3 | I7: 779 | J7: 0.38
A8: 1080686 | B8: X 70694 | C8: SALAH ROCHDI | D8: ROCHDI | E8: SALAH | F8: SPECIALISTE D'ECONOM. ET D'ADMIN. DE 2EME GR. | G8: 2 | H8: 9 | I8: 484 | J8: 0.34
A9: 1080688 | B9: KA9857 | C9: ASSYA GHAILAN EL KHARBACH | D9: GHAILAN EL KHARBACH | E9: ASSYA | F9: TECHNICIEN TROISIEME GRADE | G9: 2 | H9: 9 | I9: 404 | J9: 0.34
A10: 1154084 | B10: C 479848 | C10: JANATI MOHAMMED | D10: JANATI | E10: MOHAMMED | F10: PROF. DE L'ENS. SECOND. QUALIFIE GR. PRINCIPAL | G10: HE | H10: 2 | I10: 746 | J10: 0.38
A11: 1176381 | B11: KA30762 | C11: EL BOUCHTI ABDELAZIZ | D11: EL BOUCHTI | E11: ABDELAZIZ | F11: PROF. DE L'ENS. SECOND. COLLEGIAL 2EME GR. | G11: 2 | H11: 9 | I11: 484 | J11: 0.34
A12: 1243611 | B12: A 350922 | C12: HAJIBA BAIGA | D12: BAIGA | E12: HAJIBA | F12: ADJOINT PEDAGOGIQUE DE 5EME GRADE | G12: 2 | H12: 10 | I12: 262 | J12: 0.34
A13: 1243679 | B13: A 490131 | C13: RACHID EL ATTARI | D13: EL ATTARI | E13: RACHID | F13: TECHNICIEN DEUXIEME GRADE | G13: 2 | H13: 8 | I13: 456 | J13: 0.34
A14: 1243680 | B14: E 442797 | C14: YOUSSEF EL MERSI | D14: EL MERSI | E14: YOUSSEF | F14: TECHNICIEN DEUXIEME GRADE | G14: 2 | H14: 8 | I14: 456 | J14: 0.34
A15: 1243710 | B15: Z 166389 | C15: OMAR BOURIZK | D15: BOURIZK | E15: OMAR | F15: ADJOINT PEDAGOGIQUE DE 5EME GRADE | G15: 2 | H15: 9 | I15: 249 | J15: 0.34
A16: 1243711 | B16: KA10107 | C16: MINA TOUTI | D16: TOUTI | E16: MINA | F16: ADJOINT PEDAGOGIQUE DE 5EME GRADE | G16: 2 | H16: 9 | I16: 249 | J16: 0.34
A17: 1243714 | B17: KA5070 | C17: AMINA ADUI | D17: ADUI | E17: AMINA | F17: ADJOINT PEDAGOGIQUE DE 5EME GRADE | G17: 2 | H17: 9 | I17: 249 | J17: 0.34
A18: 1243715 | B18: C 637984 | C18: ABDLOUAHAD EL MAAROUFI | D18: EL MAAROUFI | E18: ABDELOUAHAD | F18: ADJOINT PEDAGOGIQUE DE 4EME GRADE | G18: 2 | H18: 7 | I18: 311 | J18: 0.34
A19: 1243716 | B19: P 65632 | C19: MOHAMED MARZAQUI | D19: MARZAQUI | E19: MOHAMED | F19: ADJOINT PEDAGOGIQUE DE 5EME GRADE | G19: 2 | H19: 10 | I19: 262 | J19: 0.34
A20: 1243719 | B20: K 111988 | C20: FAIZA TLIGUI | D20: TLIGUI | E20: FAIZA | F20: ADJOINT PEDAGOGIQUE DE 5EME GRADE | G20: 2 | H20: 10 | I20: 262 | J20: 0.34
A21: 1351720 | B21: X 175440 | C21: OMAR GRIJA | D21: GRIJA | E21: OMAR | F21: ADJOINT PEDAGOGIQUE DE 5EME GRADE | G21: 2 | H21: 9 | I21: 249 | J21: 0.34
A22: 1351722 | B22: X 112335 | C22: ABDELAZIZ GRIJA | D22: GRIJA | E22: ABDELAZIZ | F22: ADJOINT PEDAGOGIQUE DE 4EME GRADE | G22: 2 | H22: 8 | I22: 332 | J22: 0.34
... A25: 1351852 | B25: D 182516 | C25: MLY HAFID MAAROUFI | D25: MOULAY HAFID | E25: MAAROUFI | F25: ADJOINT PEDAGOGIQUE DE 4EME GRADE | G25: 2 | H25: 7 | I25: 311 | J25: 0.34
A26: 1410657 | B26: JB293994 | C26: OUSALAH ALI | D26: OUSALAH | E26: ALI | F26: PROF. DE L'ENS. SECOND. QUALIFIE GR. PRINCIPAL | G26: HE | H26: 1 | I26: 704 | J26: 0.38
A27: 1447725 | B27: KB23147 | C27: BEN TAIEB MONBRI ASAD | G27: 2
A28: 1495243 | B28: D 540310 | C28: 'TAGHAT KHADOUJ | D28: TAGHAT | E28: KHADOUJ | F28: SPECIALISTE D'ECONOM. ET D'ADMIN. DE 2EME GR. | G28: 2 | H28: 7 | I28: 428 | J28: 0.34
A29: 1495416 | B29: KA32499 | C29: FATIMA ZAHRAE BENABDESSADEK | D29: BENABDESSADEK | E29: FATIMA ZAHRAA | F29: ADJOINT PEDAGOGIQUE DE 5EME GRADE | G29: 2 | H29: 8 | I29: 236 | J29: 0.34
A30: 1495418 | B30: KA32974 | C30: MARYAMA BEN CHEIKH | D30: BEN-CHEIKH | E30: MARYAMA | F30: ADJOINT PEDAGOGIQUE DE 5EME GRADE | G30: 2 | H30: 8 | I30: 236 | J30: 0.34
A31: 1504127 | B31: KA32549 | C31: LAZAAR ILYASS | D31: LAZAAR | E31: ILYASS | F31: ADMINISTRATEUR PEDAGOGIQUE 1ER GRADE | G31: 1 | H31: 7 | I31: 542 | J31: 0.38
A32: 1542709 | B32: CB167116 | C32: ZERIFI ABDELAZIZ | D32: ZERIFI | E32: ABDELAZIZ | F32: PROF. DE L'ENS. SECOND. QUALIFIE GR. PRINCIPAL | G32: HE | H32: 2 | I32: 746 | J32: 0.38
A33: 1592232 | B33: K 260484 | C33: IDRISSI ABDEL KODDOUSS | D33: IDRISSI ABDEL | E33: KODDOUSS | F33: PROF. DE L'ENS. SECOND. QUALIFIE 1ER GR. | G33: 1 | H33: 7 | I33: 542 | J33: 0.38
A34: 1693093 | B34: EE234019 | C34: CHOUBHARI MOHAMED | D34: CHOUBHARI | E34: MOHAMED | F34: PROF. DE L'ENS. SECOND. COLLEGIAL 2EME GR. | G34: 2 | H34: 6 | I34: 402 | J34: 0.34
A35: 1722742 | B35: X 321466 | C35: EL ATMANI SAID | D35: EL ATMANI | E35: SAID | F35: PROF. DE L'ENS. SECOND. QUALIFIE 1ER GR. | G35: 1 | H35: 5 | I35: 472 | J35: 0.34
A36: 1756360 | B36: V 258387 | C36: AMEKAOUI SOUMIYA | D36: AMEKAOUI | E36: SOUMIYA | F36: PROF. DE L'ENS. SECOND. COLLEGIAL 2EME GR. | G36: 2 | H36: 6 | I36: 402 | J36: 0.34
A37: 1906393 | B37: OD35057 | C37: HALHOUL MHAMED | D37: HALHOUL | E37: M'HAMED | F37: PROF. DE L'ENS. SECOND. QUALIFIE 2EME GR. | G37: 2 | H37: 5 | I37: 377 | J37: 0.3
A38: 1913483 | B38: CD376801 | C38: TAKI SALMA | D38: TAKI | E38: SALMA | F38: PROF. DE L'ENS. SECOND. QUALIFIE 2EME GR. | G38: 2 | H38: 3 | I38: 326 | J38: 0.3
A39: 1914303 | B39: L 548964 | C39: MOHAMED BAZMAN | D39: BAZMAN | E39: MOHAMED | F39: PROF. AGREGE DE L'EDUCA. ET DE LA FORMA. DE 1ER GR. | G39: 1 | H39: 1 | I39: 336 | J39: 0.34
A40: 1994202 | B40: ZT118190 | C40: KARBOUB MOHAMED | D40: MOHAMED | E40: KARBOUB | F40: PROF. DE L'ENS. SECOND. QUALIFIE 2EME GR. | G40: 2 | H40: 2 | I40: 300 | J40: 0.3
A41: 2051655 | B41: U 169450 | C41: ETAIBI AYOUB | D41: ETAIBI | E41: AYOUB | F41: PROF. DE L'ENS. SECOND. QUALIFIE 2EME GR. | G41: 2 | H41: 2 | I41: 300 | J41: 0.3
A42: 2123707 | B42: GK130578 | C42: SANAE BENKHLIFA | D42: SANAE BENKHLIFA | E42: - | F42: PROF. DE L'ENS. SECOND. QUALIFIE 2EME GR. | G42: 2 | H42: 1 | I42: 275 | J42: 0.3
...

Sheet NAT
A1: Acteur Dépense | B1: Type Dépense | C1: Sous Type Dépense | D1: Loi Finance | E1: Objet Dépense | F1: Nom Signataire | G1: Prénom Signataire | H1: Date Signature | I1: (Montant)NET | J1: Mode Engagement | K1: Rubrique
A2: 0113 | B2: SALIND | C2: FRAIS_CORRECTION | D2: 2025 | E2: FRAIS DE CORRECTION EXAMEN REGIONAL 1 ER ANNEE BAC | F2: RACHID | G2: RIANE | H2: 24/06/2024 | I2: 290816 | J2: PED_GLOBAL | K2: 5212011001912015152
A6: Grade/Echelle | B6: Date début | C6: Date fin | D6: Nombre | E6: Taux | F6: Brut | G6: Retenues | H6: Montant net | I6: CIN | J6: Nom | K6: Prénom | L6: DDR | M6: Mode de paiement | N6: Type référence règlement | O6: Banque | P6: Ville | Q6: Numéoro compte Ribé | R6: Clé | S6: objet règlement | T6: Reference
A7: PROF. DE L'ENS. SECOND. QUALIFIE GR. PRINCIPAL | B7: 45803 | C7: 45819 | D7: 60 | E7: 8 | F7: 761.90476 | G7: 281.90476 | H7: 480 | I7: K 164175 | J7: EL MADANI | K7: BACHIR | L7: 743793 | M7: VIR | N7: RIB | O7: =IF(L7="","",VLOOKUP(L7,'RIB 1'!A1:F9976,3,0)) -> 230 | P7: =IF(L7="","",VLOOKUP(L7,'RIB 1'!A1:F9976,4,0)) -> 640 | Q7: =IF(L7="","",VLOOKUP(L7,'RIB 1'!A1:F9976,5,0)) -> 8576464211011800 | R7: =IF(L7="","",VLOOKUP(L7,'RIB 1'!A1:F9976,6,0)) -> 91 | S7: FRAIS_CORRECTION
A8: PROF. DE L'ENS. SECOND. QUALIFIE 2EME GR. | B8: 45803 | C8: 45819 | D8: 59 | E8: 8 | F8: 715.15152 | G8: 243.15152 | H8: 472 | I8: AB821929 | J8: BENSLIMANE | K8: HADJER | L8: 1757976 | M8: VIR | N8: RIB | O8: =IF(L8="","",VLOOKUP(L8,'RIB 1'!A2:F9977,3,0)) -> 350 | P8: =IF(L8="","",VLOOKUP(L8,'RIB 1'!A2:F9977,4,0)) -> 810 | Q8: =IF(L8="","",VLOOKUP(L8,'RIB 1'!A2:F9977,5,0)) -> 0000000006102343 | R8: =IF(L8="","",VLOOKUP(L8,'RIB 1'!A2:F9977,6,0)) -> 51 | S8: FRAIS_CORRECTION
A9: PROF. DE L'ENS. SECOND. QUALIFIE 1ER GR. | B9: 45803 | C9: 45819 | D9: 120 | E9: 8 | F9: 1523.8095 | G9: 563.80952 | H9: 960 | I9: GM79646 | J9: ZEROUAL | K9: OUSSAMA | L9: 1544261 | M9: VIR | N9: RIB | O9: =IF(L9="","",VLOOKUP(L9,'RIB 1'!A3:F9978,3,0)) -> 164 | P9: =IF(L9="","",VLOOKUP(L9,'RIB 1'!A3:F9978,4,0)) -> 640 | Q9: =IF(L9="","",VLOOKUP(L9,'RIB 1'!A3:F9978,5,0)) -> 2111199628740005 | R9: =IF(L9="","",VLOOKUP(L9,'RIB 1'!A3:F9978,6,0)) -> 68 | S9: FRAIS_CORRECTION
A10: PROF. DE L'ENS. SECOND. QUALIFIE 1ER GR. | B10: 45803 | C10: 45819 | D10: 120 | E10: 8 | F10: 1523.8095 | G10: 563.80952 | H10: 960 | I10: LB127135 | J10: HOUTTI | K10: MOHAMED | L10: 1693032 | M10: VIR | N10: RIB | O10: =IF(L10="","",VLOOKUP(L10,'RIB 1'!A4:F9979,3,0)) -> 164 | P10: =IF(L10="","",VLOOKUP(L10,'RIB 1'!A4:F9979,4,0)) -> 640 | Q10: =IF(L10="","",VLOOKUP(L10,'RIB 1'!A4:F9979,5,0)) -> 2111123269890002 | R10: =IF(L10="","",VLOOKUP(L10,'RIB 1'!A4:F9979,6,0)) -> 31 | S10: FRAIS_CORRECTION
A11: PROF. DE L'ENS. SECOND. QUALIFIE 1ER GR. | B11: 45803 | C11: 45819 | D11: 120 | E11: 8 | F11: 1454.5455 | G11: 494.54545 | H11: 960 | I11: G 428043 | J11: ESSAFI | K11: HICHAM | L11: 1722634 | M11: VIR | N11: RIB | O11: =IF(L11="","",VLOOKUP(L11,'RIB 1'!A5:F9980,3,0)) -> 007 | P11: =IF(L11="","",VLOOKUP(L11,'RIB 1'!A5:F9980,4,0)) -> 640 | Q11: =IF(L11="","",VLOOKUP(L11,'RIB 1'!A5:F9980,5,0)) -> 0004437000304069 | R11: =IF(L11="","",VLOOKUP(L11,'RIB 1'!A5:F9980,6,0)) -> 19 | S11: FRAIS_CORRECTION
A12: PROF. DE L'ENS. SECOND. QUALIFIE 2EME GR. | B12: 45803 | C12: 45819 | D12: 119 | E12: 8 | F12: 1442.4242 | G12: 490.42424 | H12: 952 | I12: KB51078 | J12: EL MAATI | K12: BOUCHTA | L12: 1546515 | M12: VIR | N12: RIB | O12: =IF(L12="","",VLOOKUP(L12,'RIB 1'!A6:F9981,3,0)) -> 360 | P12: =IF(L12="","",VLOOKUP(L12,'RIB 1'!A6:F9981,4,0)) -> 640 | Q12: =IF(L12="","",VLOOKUP(L12,'RIB 1'!A6:F9981,5,0)) -> 0000086216850027 | R12: =IF(L12="","",VLOOKUP(L12,'RIB 1'!A6:F9981,6,0)) -> 20 | S12: FRAIS_CORRECTION
A13: PROF. DE L'ENS. SECOND. QUALIFIE 2EME GR. | B13: 45803 | C13: 45819 | D13: 60 | E13: 8 | F13: 727.27273 | G13: 247.27273 | H13: 480 | I13: K 199690 | J13: TLIDI | K13: ABDELAZIZ | L13: 1689331 | M13: VIR | N13: RIB | O13: =IF(L13="","",VLOOKUP(L13,'RIB 1'!A7:F9982,3,0)) -> 230 | P13: =IF(L13="","",VLOOKUP(L13,'RIB 1'!A7:F9982,4,0)) -> 640 | Q13: =IF(L13="","",VLOOKUP(L13,'RIB 1'!A7:F9982,5,0)) -> 4647269211011800 | R13: =IF(L13="","",VLOOKUP(L13,'RIB 1'!A7:F9982,6,0)) -> 74 | S13: FRAIS_CORRECTION
A14: PROF. DE L'ENS. SECOND. QUALIFIE 2EME GR. | B14: 45803 | C14: 45819 | D14: 120 | E14: 8 | F14: 1371.4286 | G14: 411.42857 | H14: 960 | I14: HH4429 | J14: ANTAR | K14: FATIMA-EZZAHRA | L14: 1905442 | M14: VIR | N14: RIB | O14: =IF(L14="","",VLOOKUP(L14,'RIB 1'!A8:F9983,3,0)) -> 360 | P14: =IF(L14="","",VLOOKUP(L14,'RIB 1'!A8:F9983,4,0)) -> 640 | Q14: =IF(L14="","",VLOOKUP(L14,'RIB 1'!A8:F9983,5,0)) -> 0000049065490012 | R14: =IF(L14="","",VLOOKUP(L14,'RIB 1'!A8:F9983,6,0)) -> 67 | S14: FRAIS_CORRECTION
A15: PROF. DE L'ENS. SECOND. QUALIFIE 1ER GR. | B15: 45803 | C15: 45819 | D15: 120 | E15: 8 | F15: 1523.8095 | G15: 563.80952 | H15: 960 | I15: LA100494 | J15: KCHIKICH | K15: BOUCHRA | L15: 1693025 | M15: VIR | N15: RIB | O15: =IF(L15="","",VLOOKUP(L15,'RIB 1'!A9:F9984,3,0)) -> 011 | P15: =IF(L15="","",VLOOKUP(L15,'RIB 1'!A9:F9984,4,0)) -> 640 | Q15: =IF(L15="","",VLOOKUP(L15,'RIB 1'!A9:F9984,5,0)) -> 0000162000003795 | R15: =IF(L15="","",VLOOKUP(L15,'RIB 1'!A9:F9984,6,0)) -> 27 | S15: FRAIS_CORRECTION
A16: PROF. DE L'ENS. SECOND. QUALIFIE 2EME GR. | B16: 45803 | C16: 45819 | D16: 60 | E16: 8 | F16: 727.27273 | G16: 247.27273 | H16: 480 | I16: K 450414 | J16: CHOJAA | K16: MOHAMED LARBI | L16: 1722620 | M16: VIR | N16: RIB | O16: =IF(L16="","",VLOOKUP(L16,'RIB 1'!A10:F9985,3,0)) -> 021 | P16: =IF(L16="","",VLOOKUP(L16,'RIB 1'!A10:F9985,4,0)) -> 640 | Q16: =IF(L16="","",VLOOKUP(L16,'RIB 1'!A10:F9985,5,0)) -> 0000233001063597 | R16: =IF(L16="","",VLOOKUP(L16,'RIB 1'!A10:F9985,6,0)) -> 95 | S16: FRAIS_CORRECTION
A17: PROF. DE L'ENS. SECOND. QUALIFIE 2EME GR. | B17: 45803 | C17: 45819 | D17: 180 | E17: 8 | F17: 2057.1429 | G17: 617.14286 | H17: 1440 | I17: K 510659 | J17: BAKKALI | K17: GHAZOUANI MOHAMMED | L17: 1906047 | M17: VIR | N17: RIB | O17: =IF(L17="","",VLOOKUP(L17,'RIB 1'!A11:F9986,3,0)) -> 230 | P17: =IF(L17="","",VLOOKUP(L17,'RIB 1'!A11:F9986,4,0)) -> 640 | Q17: =IF(L17="","",VLOOKUP(L17,'RIB 1'!A11:F9986,5,0)) -> 7539114211006000 | R17: =IF(L17="","",VLOOKUP(L17,'RIB 1'!A11:F9986,6,0)) -> 94 | S17: FRAIS_CORRECTION
A18: PROF. DE L'ENS. SECOND. QUALIFIE 2EME GR. | B18: 45803 | C18: 45819 | D18: 120 | E18: 8 | F18: 1371.4286 | G18: 411.42857 | H18: 960 | I18: L 534627 | J18: BOUABADI | K18: YOUSRA | L18: 1966971 | M18: VIR | N18: RIB | O18: =IF(L18="","",VLOOKUP(L18,'RIB 1'!A12:F9987,3,0)) -> 164 | P18: =IF(L18="","",VLOOKUP(L18,'RIB 1'!A12:F9987,4,0)) -> 720 | Q18: =IF(L18="","",VLOOKUP(L18,'RIB 1'!A12:F9987,5,0)) -> 2111119126020007 | R18: =IF(L18="","",VLOOKUP(L18,'RIB 1'!A12:F9987,6,0)) -> 58 | S18: FRAIS_CORRECTION
... A275: PROF. DE L'ENS. SECOND. QUALIFIE GR. PRINCIPAL | B275: 45803 | C275: 45819 | D275: 119 | E275: 8 | F275: 1511.1111 | G275: 559.11111 | H275: 952 | I275: K 246379 | J275: AMTOT | K275: TOURIA | L275: 1121589 | M275: VIR | N275: RIB | O275: =IF(L275="","",VLOOKUP(L275,'RIB 1'!A269:F10244,3,0)) -> 164 | P275: =IF(L275="","",VLOOKUP(L275,'RIB 1'!A269:F10244,4,0)) -> 640 | Q275: =IF(L275="","",VLOOKUP(L275,'RIB 1'!A269:F10244,5,0)) -> 2111153272870006 | R275: =IF(L275="","",VLOOKUP(L275,'RIB 1'!A269:F10244,6,0)) -> 68 | S275: FRAIS_CORRECTION

Sheet centre 9
A1: Acteur Dépense | B1: Type Dépense | C1: Sous Type Dépense | D1: Loi Finance | E1: Objet Dépense | F1: Nom Signataire | G1: Prénom Signataire | H1: Date Signature | I1: (Montant)NET | J1: Mode Engagement | K1: Rubrique
A2: 0113 | B2: SALIND | D2: 2025 | E2: INDEMNITES POUR L'ORGANISATION DES EXAMENS ET CONCOURS 6 EME ANNEE COLLEGIAL | F2: RACHID | G2: RIANE | H2: 27/06/2025 | I2: =SUM(H7:H24) -> 30600 | J2: PED_GLOBAL | K2: 5212011001912015153
A6: Grade/Echelle | B6: Date début | C6: Date fin | D6: Nombre | E6: Taux | F6: Brut | G6: Retenues | H6: Montant net | I6: CIN | J6: Nom | K6: Prénom | L6: DDR | M6: Mode de paiement | N6: Type référence règlement | O6: Banque | P6: Ville | Q6: Numéoro compte Ribé | R6: Clé | S6: objet règlement | T6: Reference
A7: PROF. DE L'ENS. SECOND. QUALIFIE GR. PRINCIPAL | B7: 28/05/2025 | C7: 27/06/2025 | D7: 6 | E7: 300 | F7: 1800 | G7: 0 | H7: 1800 | I7: FC18719 | J7: ABDOUS | K7: HABIBA | L7: 1276705 | M7: VIR | N7: RIB | O7: =IF(L7="","",VLOOKUP(L7,'RIB 1'!A1:F9976,3,0)) -> 164 | P7: =IF(L7="","",VLOOKUP(L7,'RIB 1'!A1:F9976,4,0)) -> 640 | Q7: =IF(L7="","",VLOOKUP(L7,'RIB 1'!A1:F9976,5,0)) -> 2111134184050002 | R7: =IF(L7="","",VLOOKUP(L7,'RIB 1'!A1:F9976,6,0)) -> 11 | S7: FRAIS_CORRECTION
A8: SPECIALISTE PEDAGOGIQUE DE 2EME GR. | B8: 28/05/2025 | C8: 27/06/2025 | D8: 6 | E8: 300 | F8: 1800 | G8: 0 | H8: 1800 | I8: LA76577 | J8: JBILOU | K8: SAMIR | L8: 1680403 | M8: VIR | N8: RIB | O8: =IF(L8="","",VLOOKUP(L8,'RIB 1'!A2:F9977,3,0)) -> 007 | P8: =IF(L8="","",VLOOKUP(L8,'RIB 1'!A2:F9977,4,0)) -> 640 | Q8: =IF(L8="","",VLOOKUP(L8,'RIB 1'!A2:F9977,5,0)) -> 0004422000304570 | R8: =IF(L8="","",VLOOKUP(L8,'RIB 1'!A2:F9977,6,0)) -> 46 | S8: FRAIS_CORRECTION
A9: PROF. DE L'ENS. PRIMAIRE 1ER GR. | B9: 28/05/2025 | C9: 27/06/2025 | D9: 6 | E9: 300 | F9: 1800 | G9: 0 | H9: 1800 | I9: K 250280 | J9: EL FARGANI | K9: MOHAMED | L9: 1116474 | M9: VIR | N9: RIB | O9: =IF(L9="","",VLOOKUP(L9,'RIB 1'!A3:F9978,3,0)) -> 011 | P9: =IF(L9="","",VLOOKUP(L9,'RIB 1'!A3:F9978,4,0)) -> 640 | Q9: =IF(L9="","",VLOOKUP(L9,'RIB 1'!A3:F9978,5,0)) -> 0000072000006717 | R9: =IF(L9="","",VLOOKUP(L9,'RIB 1'!A3:F9978,6,0)) -> 53 | S9: FRAIS_CORRECTION
A10: SPECIALISTE D'ECONOM. ET D'ADMIN. DE 1ER GR. | B10: 28/05/2025 | C10: 27/06/2025 | D10: 6 | E10: 300 | F10: 1800 | G10: 0 | H10: 1800 | I10: K 259084 | J10: ABJAYOU | K10: MOHAMMED | L10: 1116506 | M10: VIR | N10: RIB | O10: =IF(L10="","",VLOOKUP(L10,'RIB 1'!A4:F9979,3,0)) -> 164 | P10: =IF(L10="","",VLOOKUP(L10,'RIB 1'!A4:F9979,4,0)) -> 640 | Q10: =IF(L10="","",VLOOKUP(L10,'RIB 1'!A4:F9979,5,0)) -> 2111155612930002 | R10: =IF(L10="","",VLOOKUP(L10,'RIB 1'!A4:F9979,6,0)) -> 13 | S10: FRAIS_CORRECTION
A11: SPECIALISTE D'ECONOM. ET D'ADMIN. DE 1ER GR. | B11: 28/05/2025 | C11: 27/06/2025 | D11: 6 | E11: 300 | F11: 1800 | G11: 0 | H11: 1800 | I11: K 209741 | J11: SBAYJI | K11: MOHAMMED SAID | L11: 57611 | M11: VIR | N11: RIB | O11: =IF(L11="","",VLOOKUP(L11,'RIB 1'!A5:F9980,3,0)) -> 164 | P11: =IF(L11="","",VLOOKUP(L11,'RIB 1'!A5:F9980,4,0)) -> 640 | Q11: =IF(L11="","",VLOOKUP(L11,'RIB 1'!A5:F9980,5,0)) -> 2111153307550003 | R11: =IF(L11="","",VLOOKUP(L11,'RIB 1'!A5:F9980,6,0)) -> 46 | S11: FRAIS_CORRECTION
A12: SPECIALISTE D'ECONOM. ET D'ADMIN. DE 1ER GR. | B12: 28/05/2025 | C12: 27/06/2025 | D12: 6 | E12: 300 | F12: 1800 | G12: 0 | H12: 1800 | I12: K 239856 | J12: CHARAB | K12: BADREDDINE | L12: 55990 | M12: VIR | N12: RIB | O12: =IF(L12="","",VLOOKUP(L12,'RIB 1'!A6:F9981,3,0)) -> 164 | P12: =IF(L12="","",VLOOKUP(L12,'RIB 1'!A6:F9981,4,0)) -> 640 | Q12: =IF(L12="","",VLOOKUP(L12,'RIB 1'!A6:F9981,5,0)) -> 2111133277330008 | R12: =IF(L12="","",VLOOKUP(L12,'RIB 1'!A6:F9981,6,0)) -> 51 | S12: FRAIS_CORRECTION
A13: ADJOINT PEDAGOGIQUE DE 4EME GRADE | B13: 28/05/2025 | C13: 27/06/2025 | D13: 6 | E13: 300 | F13: 1800 | G13: 0 | H13: 1800 | I13: K 230978 | J13: CHEOUATI | K13: AHMED | L13: 1403729 | M13: VIR | N13: RIB | O13: =IF(L13="","",VLOOKUP(L13,'RIB 1'!A7:F9982,3,0)) -> 164 | P13: =IF(L13="","",VLOOKUP(L13,'RIB 1'!A7:F9982,4,0)) -> 640 | Q13: =IF(L13="","",VLOOKUP(L13,'RIB 1'!A7:F9982,5,0)) -> 2111133319680014 | R13: =IF(L13="","",VLOOKUP(L13,'RIB 1'!A7:F9982,6,0)) -> 51 | S13: FRAIS_CORRECTION
A14: ADJOINT PEDAGOGIQUE DE 5EME GRADE | B14: 28/05/2025 | C14: 27/06/2025 | D14: 4 | E14: 300 | F14: 1200 | G14: 0 | H14: 1200 | I14: K 149401 | J14: MAIMOUNI | K14: MOHAMMED | L14: 1310759 | M14: VIR | N14: RIB | O14: =IF(L14="","",VLOOKUP(L14,'RIB 1'!A8:F9983,3,0)) -> 164 | P14: =IF(L14="","",VLOOKUP(L14,'RIB 1'!A8:F9983,4,0)) -> 640 | Q14: =IF(L14="","",VLOOKUP(L14,'RIB 1'!A8:F9983,5,0)) -> 2111178014970004 | R14: =IF(L14="","",VLOOKUP(L14,'RIB 1'!A8:F9983,6,0)) -> 13 | S14: FRAIS_CORRECTION
A15: ADJOINT PEDAGOGIQUE DE 4EME GRADE | B15: 28/05/2025 | C15: 27/06/2025 | D15: 4 | E15: 300 | F15: 1200 | G15: 0 | H15: 1200 | I15: K 251744 | J15: BELHADRI | K15: MAROUANE | L15: 1398949 | M15: VIR | N15: RIB | O15: =IF(L15="","",VLOOKUP(L15,'RIB 1'!A9:F9984,3,0)) -> 230 | P15: =IF(L15="","",VLOOKUP(L15,'RIB 1'!A9:F9984,4,0)) -> 640 | Q15: =IF(L15="","",VLOOKUP(L15,'RIB 1'!A9:F9984,5,0)) -> 5589759211011800 | R15: =IF(L15="","",VLOOKUP(L15,'RIB 1'!A9:F9984,6,0)) -> 78 | S15: FRAIS_CORRECTION
A16: ADJOINT PEDAGOGIQUE DE 4EME GRADE | B16: 28/05/2025 | C16: 27/06/2025 | D16: 4 | E16: 300 | F16: 1200 | G16: 0 | H16: 1200 | I16: K 176035 | J16: AOUDAIR | K16: MOHAMED | L16: 1310711 | M16: VIR | N16: RIB | O16: =IF(L16="","",VLOOKUP(L16,'RIB 1'!A10:F9985,3,0)) -> 164 | P16: =IF(L16="","",VLOOKUP(L16,'RIB 1'!A10:F9985,4,0)) -> 640 | Q16: =IF(L16="","",VLOOKUP(L16,'RIB 1'!A10:F9985,5,0)) -> 2111133175420000 | R16: =IF(L16="","",VLOOKUP(L16,'RIB 1'!A10:F9985,6,0)) -> 43 | S16: FRAIS_CORRECTION
A17: ADMINISTRATEUR DE L’EDUCA. NAT. DE GR. PRINCIPAL | B17: 28/05/2025 | C17: 27/06/2025 | D17: 6 | E17: 300 | F17: 1800 | G17: 0 | H17: 1800 | I17: K 200805 | J17: BEN KADUR | K17: EL MOSTAFA | L17: 63702 | M17: VIR | N17: RIB | O17: =IF(L17="","",VLOOKUP(L17,'RIB 1'!A11:F9986,3,0)) -> 230 | P17: =IF(L17="","",VLOOKUP(L17,'RIB 1'!A11:F9986,4,0)) -> 640 | Q17: =IF(L17="","",VLOOKUP(L17,'RIB 1'!A11:F9986,5,0)) -> 7259971211006000 | R17: =IF(L17="","",VLOOKUP(L17,'RIB 1'!A11:F9986,6,0)) -> 76 | S17: FRAIS_CORRECTION
A18: SPECIALISTE PEDAGOGIQUE DE 2EME GR. | B18: 28/05/2025 | C18: 27/06/2025 | D18: 6 | E18: 300 | F18: 1800 | G18: 0 | H18: 1800 | I18: JC369603 | J18: AIT HMMADI | K18: MOHAMED | L18: 1680411 | M18: VIR | N18: RIB | O18: =IF(L18="","",VLOOKUP(L18,'RIB 1'!A12:F9987,3,0)) -> 350 | P18: =IF(L18="","",VLOOKUP(L18,'RIB 1'!A12:F9987,4,0)) -> 810 | Q18: =IF(L18="","",VLOOKUP(L18,'RIB 1'!A12:F9987,5,0)) -> 0000000001815687 | R18: =IF(L18="","",VLOOKUP(L18,'RIB 1'!A12:F9987,6,0)) -> 50 | S18: FRAIS_CORRECTION
... A24: PROF. DE L'ENS. SECOND. COLLEGIAL 1ER GR. | B24: 28/05/2025 | C24: 27/06/2025 | D24: 6 | E24: 300 | F24: 1800 | G24: 0 | H24: 1800 | I24: K 214828 | J24: ROUDANI | K24: ABDELAZIZ | L24: 1045515 | M24: VIR | N24: RIB | O24: =IF(L24="","",VLOOKUP(L24,'RIB 1'!A18:F9993,3,0)) -> 362 | P24: =IF(L24="","",VLOOKUP(L24,'RIB 1'!A18:F9993,4,0)) -> 640 | Q24: =IF(L24="","",VLOOKUP(L24,'RIB 1'!A18:F9993,5,0)) -> 0011112000806128 | R24: =IF(L24="","",VLOOKUP(L24,'RIB 1'!A18:F9993,6,0)) -> 85 | S24: FRAIS_CORRECTION

Sheet liate5
A1: Acteur Dépense | B1: Type Dépense | C1: Sous Type Dépense | D1: Loi Finance | E1: Objet Dépense | F1: Nom Signataire | G1: Prénom Signataire | H1: Date Signature | I1: (Montant)NET | J1: Mode Engagement | K1: Rubrique
A2: 0113 | B2: SALIND | C2: IND_SUPP | D2: 2026 | E2: INDEMNITE HORAIRE POUR TRAVAUX SUPPLEMENTAIRES - SOUTIEN SCOLAIRE Liste N°=14 | F2: RACHID | G2: RIANE | I2: =SUM(H7:H107) -> 355312.53 | J2: PED_GLOBAL | K2: 5212011001912013321
A6: Grade/Echelle | B6: Date début | C6: Date fin | D6: Nombre | E6: Taux | F6: Brut | G6: Retenues | H6: Montant net | I6: CIN | J6: Nom | K6: Prénom | L6: DDR | M6: Mode de paiement | N6: Type référence règlement | O6: RIB | P6: Banque | Q6: Ville | R6: Numéoro compte Ribé | S6: Clé | T6: objet règlement | U6: Reference | V6: Nom & Prénom
A7: PROF. DE L'ENS. PRIMAIRE 2EME GR. | B7: 02/01/2026 | C7: 30/06/2026 | D7: 28 | E7: 159 | F7: 4452 | G7: 1513.68 | H7: 2938.32 | I7: K 340095 | J7: =X7 -> RABHIOUI | K7: =Y7 -> ATIKA | L7: 1239069 | M7: VIR | N7: RIB | O7: 360640000003489265001435 | P7: =LEFT(O7,3) -> 360 | Q7: =RIGHT(LEFTB(O7,6),3) -> 640 | R7: =RIGHT(LEFTB(O7,22),16) -> 0000034892650014 | S7: =RIGHT(O7,2) -> 35 | T7: IND_SUPP | U7: IND_SUPP | V7: RABHIOUI ATIKA | W7: 1 | X7: =LEFT(V7,SEARCH(" ",V7)-1) -> RABHIOUI | Y7: =IFERROR(MID(TRIM(V7),SEARCH(" ",TRIM(V7))+1,999),"") -> ATIKA
A8: PROF. DE L'ENS. PRIMAIRE 1ER GR. | B8: 02/01/2026 | C8: 30/06/2026 | D8: 28 | E8: 159 | F8: 4452 | G8: 1647.24 | H8: 2804.76 | I8: K 175922 | J8: =X8 -> ROUDANI | K8: =Y8 -> RACHID | L8: 749492 | M8: VIR | N8: RIB | O8: 164640211113331605000582 | P8: =LEFT(O8,3) -> 164 | Q8: =RIGHT(LEFTB(O8,6),3) -> 640 | R8: =RIGHT(LEFTB(O8,22),16) -> 2111133316050005 | S8: =RIGHT(O8,2) -> 82 | T8: IND_SUPP | U8: IND_SUPP | V8: ROUDANI RACHID | W8: 2 | X8: =LEFT(V8,SEARCH(" ",V8)-1) -> ROUDANI | Y8: =IFERROR(MID(TRIM(V8),SEARCH(" ",TRIM(V8))+1,999),"") -> RACHID
A9: PROF. DE L'ENS. PRIMAIRE 1ER GR. | B9: 02/01/2026 | C9: 30/06/2026 | D9: 24 | E9: 159 | F9: 3816 | G9: 1411.92 | H9: 2404.08 | I9: GK48612 | J9: =X9 -> AHDI | K9: =Y9 -> ABDELFETTAH | L9: 1120532 | M9: VIR | N9: RIB | O9: 230640509097421102800033 | P9: =LEFT(O9,3) -> 230 | Q9: =RIGHT(LEFTB(O9,6),3) -> 640 | R9: =RIGHT(LEFTB(O9,22),16) -> 5090974211028000 | S9: =RIGHT(O9,2) -> 33 | T9: IND_SUPP | U9: IND_SUPP | V9: AHDI ABDELFETTAH | W9: 3 | X9: =LEFT(V9,SEARCH(" ",V9)-1) -> AHDI | Y9: =IFERROR(MID(TRIM(V9),SEARCH(" ",TRIM(V9))+1,999),"") -> ABDELFETTAH
A10: PROF. DE L'ENS. PRIMAIRE 2EME GR. | B10: 02/01/2026 | C10: 30/06/2026 | D10: 8 | E10: 159 | F10: 1272 | G10: 432.48 | H10: 839.52 | I10: K 340095 | J10: =X10 -> RABHIOUI | K10: =Y10 -> ATIKA | L10: 1239069 | M10: VIR | N10: RIB | O10: 360640000003489265001435 | P10: =LEFT(O10,3) -> 360 | Q10: =RIGHT(LEFTB(O10,6),3) -> 640 | R10: =RIGHT(LEFTB(O10,22),16) -> 0000034892650014 | S10: =RIGHT(O10,2) -> 35 | T10: IND_SUPP | U10: IND_SUPP | V10: RABHIOUI ATIKA | W10: 4 | X10: =LEFT(V10,SEARCH(" ",V10)-1) -> RABHIOUI | Y10: =IFERROR(MID(TRIM(V10),SEARCH(" ",TRIM(V10))+1,999),"") -> ATIKA
A11: PROF. DE L'ENS. PRIMAIRE 1ER GR. | B11: 02/01/2026 | C11: 30/06/2026 | D11: 8 | E11: 159 | F11: 1272 | G11: 470.64 | H11: 801.36 | I11: K 175922 | J11: =X11 -> ROUDANI | K11: =Y11 -> RACHID | L11: 749492 | M11: VIR | N11: RIB | O11: 164640211113331605000582 | P11: =LEFT(O11,3) -> 164 | Q11: =RIGHT(LEFTB(O11,6),3) -> 640 | R11: =RIGHT(LEFTB(O11,22),16) -> 2111133316050005 | S11: =RIGHT(O11,2) -> 82 | T11: IND_SUPP | U11: IND_SUPP | V11: ROUDANI RACHID | W11: 5 | X11: =LEFT(V11,SEARCH(" ",V11)-1) -> ROUDANI | Y11: =IFERROR(MID(TRIM(V11),SEARCH(" ",TRIM(V11))+1,999),"") -> RACHID
A12: PROF. DE L'ENS. PRIMAIRE 1ER GR. | B12: 02/01/2026 | C12: 30/06/2026 | D12: 10 | E12: 159 | F12: 1590 | G12: 588.3 | H12: 1001.7 | I12: GK48612 | J12: =X12 -> AHDI | K12: =Y12 -> ABDELFETTAH | L12: 1120532 | M12: VIR | N12: RIB | O12: 230640509097421102800033 | P12: =LEFT(O12,3) -> 230 | Q12: =RIGHT(LEFTB(O12,6),3) -> 640 | R12: =RIGHT(LEFTB(O12,22),16) -> 5090974211028000 | S12: =RIGHT(O12,2) -> 33 | T12: IND_SUPP | U12: IND_SUPP | V12: AHDI ABDELFETTAH | W12: 6 | X12: =LEFT(V12,SEARCH(" ",V12)-1) -> AHDI | Y12: =IFERROR(MID(TRIM(V12),SEARCH(" ",TRIM(V12))+1,999),"") -> ABDELFETTAH
A13: PROF. DE L'ENS. PRIMAIRE 1ER GR. | B13: 02/01/2026 | C13: 30/06/2026 | D13: 14 | E13: 159 | F13: 2226 | G13: 823.62 | H13: 1402.38 | I13: K 180147 | J13: =X13 -> ER-RAMACH | K13: =Y13 -> RAJAE | L13: 63001 | M13: VIR | N13: RIB | O13: 164640211113328100000157 | P13: =LEFT(O13,3) -> 164 | Q13: =RIGHT(LEFTB(O13,6),3) -> 640 | R13: =RIGHT(LEFTB(O13,22),16) -> 2111133281000001 | S13: =RIGHT(O13,2) -> 57 | T13: IND_SUPP | U13: IND_SUPP | V13: ER-RAMACH RAJAE | W13: 7 | X13: =LEFT(V13,SEARCH(" ",V13)-1) -> ER-RAMACH | Y13: =IFERROR(MID(TRIM(V13),SEARCH(" ",TRIM(V13))+1,999),"") -> RAJAE
